<robot name="Mks_Saxx_1500">
  <material name="orange">
    <color rgba="1.0 0.5 0.2 1" />
  </material>
  <material name="gray">
    <color rgba="0.2 0.2 0.2 1" />
  </material>

  <link name="base_link">
   <visual>
    <geometry><box size="3.0 1.5 1.5"/></geometry>
    <origin xyz="0 0 0.75"/>
   </visual>
   <collision>
    <geometry><box size="3.0 1.5 1.5"/></geometry>
    <origin xyz="0 0 1"/>
   </collision>
  </link>
  
  <link name="front_left_wheel">
   <visual><material name="gray">
    <color rgba="0 0 0 1" />
  </material>
  <origin xyz="0 0 0.25" rpy="0 1.5708 1.5708"/><geometry><cylinder radius="0.25" length="0.1"/></geometry></visual>
   <collision>
    <geometry><cylinder radius="0.25" length="0.1"/></geometry><origin xyz="0 0 0.25" rpy="0 1.5708 0"/>
   </collision>
   <inertial>
    <origin xyz="0 0 0" rpy="0 1.5708 0"/>
    <mass value="5"/>
    <inertia ixx="0.1" iyy="0.1" izz="0.1" ixy="0" ixz="0" iyz="0"/>
   </inertial>

  </link>

  <link name="front_right_wheel">
   <visual><material name="gray">
    <color rgba="0 0 0 1" />
  </material><origin xyz="0 0 0" rpy="0 1.5708 1.5708"/><geometry><cylinder radius="0.25" length="0.1"/></geometry></visual>
   <collision>
    <geometry><cylinder radius="0.25" length="0.1"/></geometry>
   </collision>
   <inertial>
    <origin xyz="0 0 0" rpy="0 0 0"/>
    <mass value="5"/>
    <inertia ixx="0.1" iyy="0.1" izz="0.1" ixy="0" ixz="0" iyz="0"/>
   </inertial>

  </link>

  <link name="rear_left_wheel">
   <visual><material name="gray">
    <color rgba="0 0 0 1" />
  </material><origin xyz="0 0 0" rpy="0 1.5708 1.5708"/><geometry><cylinder radius="0.25" length="0.1"/></geometry></visual>
   <collision>
    <geometry><cylinder radius="0.25" length="0.1"/></geometry>
   </collision>
   <inertial>
    <origin xyz="0 0 0" rpy="0 0 0"/>
    <mass value="5"/>
    <inertia ixx="0.1" iyy="0.1" izz="0.1" ixy="0" ixz="0" iyz="0"/>
   </inertial>

  </link>

  <link name="rear_right_wheel">
   <visual><material name="gray">
    <color rgba="0 0 0 1" />
  </material><origin xyz="0 0 0" rpy="0 1.5708 1.5708"/><geometry><cylinder radius="0.25" length="0.1"/></geometry></visual>
   <collision>
    <geometry><cylinder radius="0.25" length="0.1"/></geometry>
   </collision>
   <inertial>
    <origin xyz="0 0 0" rpy="0 0 0"/>
    <mass value="5"/>
    <inertia ixx="0.1" iyy="0.1" izz="0.1" ixy="0" ixz="0" iyz="0"/>
   </inertial>

  </link>

  <link name="laser_link">
    <visual>
     <origin xyz="0 0 0" />
     <geometry>
      <box size="0.1 0.1 0.05" />
     </geometry>
     <material name="red" />
    </visual>
    <collision>
     <origin xyz="0 0 0" />
     <geometry>
      <box size="0.96 0.66 0.58" />
     </geometry>
     <material name="red" />
    </collision>
  </link>

  <joint name="laser_joint" type="fixed">
    <parent link="base_link"/>
    <child link="laser_link"/>
    <origin xyz="2 0 -0.3" rpy="0 0 3.1459"/>
  </joint>

  <joint name="rear_left_wheel_joint" type="continuous">
    <parent link="base_link"/>
    <child link="rear_left_wheel"/>
    <origin xyz="-1.2 0.75 0.0" rpy="0 0 0"/>
    <axis xyz="0 1 0"/>
  </joint>

  <joint name="rear_right_wheel_joint" type="continuous">
    <parent link="base_link"/>
    <child link="rear_right_wheel"/>
    <origin xyz="-1.2 -0.75 0.0" rpy="0 0 0"/>
    <axis xyz="0 1 0"/>
  </joint>

  <joint name="front_left_wheel_joint" type="continuous">
    <parent link="base_link"/>
    <child link="front_left_wheel"/>
    <origin xyz="1.2 0.75 0.0" rpy="0 0 0"/>
    <axis xyz="0 0 1"/>
  </joint>

  <joint name="front_right_wheel_joint" type="continuous">
    <parent link="base_link"/>
    <child link="front_right_wheel"/>
    <origin xyz="1.2 -0.75 0.0" rpy="0 0 0"/>
    <axis xyz="0 0 1"/>
  </joint>

</robot>
